Workbook

Sheet Overview
A1: JLPT N5 Tutor — Test Scenarios by Specialist Perspective
A2: Generated from the 84-perspective list (categories A–N). Each tab = one category.
A3: Writing-discipline note: every scenario phrasing is bounded — names exactly what is scanned/sampled. No claim implies universal coverage. A future JLPT exam, native reviewer, or institutional adopter may surface item classes outside what is captured here.
A5: Tab | B5: Scenarios | C5: P1 | D5: P2 | E5: P3 | F5: P4 + P5
A6: A. Japanese language | B6: =COUNTA('A. Japanese language'!A5:A1000) | C6: =COUNTIF('A. Japanese language'!G5:G1000, "P1") | D6: =COUNTIF('A. Japanese language'!G5:G1000, "P2") | E6: =COUNTIF('A. Japanese language'!G5:G1000, "P3") | F6: =COUNTIF('A. Japanese language'!G5:G1000, "P4") + COUNTIF('A. Japanese language'!G5:G1000, "P5")
A7: B. JLPT format | B7: =COUNTA('B. JLPT format'!A5:A1000) | C7: =COUNTIF('B. JLPT format'!G5:G1000, "P1") | D7: =COUNTIF('B. JLPT format'!G5:G1000, "P2") | E7: =COUNTIF('B. JLPT format'!G5:G1000, "P3") | F7: =COUNTIF('B. JLPT format'!G5:G1000, "P4") + COUNTIF('B. JLPT format'!G5:G1000, "P5")
A8: C. Hindi locale | B8: =COUNTA('C. Hindi locale'!A5:A1000) | C8: =COUNTIF('C. Hindi locale'!G5:G1000, "P1") | D8: =COUNTIF('C. Hindi locale'!G5:G1000, "P2") | E8: =COUNTIF('C. Hindi locale'!G5:G1000, "P3") | F8: =COUNTIF('C. Hindi locale'!G5:G1000, "P4") + COUNTIF('C. Hindi locale'!G5:G1000, "P5")
A9: D. UX design | B9: =COUNTA('D. UX design'!A5:A1000) | C9: =COUNTIF('D. UX design'!G5:G1000, "P1") | D9: =COUNTIF('D. UX design'!G5:G1000, "P2") | E9: =COUNTIF('D. UX design'!G5:G1000, "P3") | F9: =COUNTIF('D. UX design'!G5:G1000, "P4") + COUNTIF('D. UX design'!G5:G1000, "P5")
A10: E. Accessibility | B10: =COUNTA('E. Accessibility'!A5:A1000) | C10: =COUNTIF('E. Accessibility'!G5:G1000, "P1") | D10: =COUNTIF('E. Accessibility'!G5:G1000, "P2") | E10: =COUNTIF('E. Accessibility'!G5:G1000, "P3") | F10: =COUNTIF('E. Accessibility'!G5:G1000, "P4") + COUNTIF('E. Accessibility'!G5:G1000, "P5")
A11: F. Security | B11: =COUNTA('F. Security'!A5:A1000) | C11: =COUNTIF('F. Security'!G5:G1000, "P1") | D11: =COUNTIF('F. Security'!G5:G1000, "P2") | E11: =COUNTIF('F. Security'!G5:G1000, "P3") | F11: =COUNTIF('F. Security'!G5:G1000, "P4") + COUNTIF('F. Security'!G5:G1000, "P5")
A12: G. Privacy and legal | B12: =COUNTA('G. Privacy and legal'!A5:A1000) | C12: =COUNTIF('G. Privacy and legal'!G5:G1000, "P1") | D12: =COUNTIF('G. Privacy and legal'!G5:G1000, "P2") | E12: =COUNTIF('G. Privacy and legal'!G5:G1000, "P3") | F12: =COUNTIF('G. Privacy and legal'!G5:G1000, "P4") + COUNTIF('G. Privacy and legal'!G5:G1000, "P5")
A13: H. Performance | B13: =COUNTA('H. Performance'!A5:A1000) | C13: =COUNTIF('H. Performance'!G5:G1000, "P1") | D13: =COUNTIF('H. Performance'!G5:G1000, "P2") | E13: =COUNTIF('H. Performance'!G5:G1000, "P3") | F13: =COUNTIF('H. Performance'!G5:G1000, "P4") + COUNTIF('H. Performance'!G5:G1000, "P5")
A14: I. Data engineering | B14: =COUNTA('I. Data engineering'!A5:A1000) | C14: =COUNTIF('I. Data engineering'!G5:G1000, "P1") | D14: =COUNTIF('I. Data engineering'!G5:G1000, "P2") | E14: =COUNTIF('I. Data engineering'!G5:G1000, "P3") | F14: =COUNTIF('I. Data engineering'!G5:G1000, "P4") + COUNTIF('I. Data engineering'!G5:G1000, "P5")
A15: J. Pedagogy | B15: =COUNTA('J. Pedagogy'!A5:A1000) | C15: =COUNTIF('J. Pedagogy'!G5:G1000, "P1") | D15: =COUNTIF('J. Pedagogy'!G5:G1000, "P2") | E15: =COUNTIF('J. Pedagogy'!G5:G1000, "P3") | F15: =COUNTIF('J. Pedagogy'!G5:G1000, "P4") + COUNTIF('J. Pedagogy'!G5:G1000, "P5")
A16: K. QA testing | B16: =COUNTA('K. QA testing'!A5:A1000) | C16: =COUNTIF('K. QA testing'!G5:G1000, "P1") | D16: =COUNTIF('K. QA testing'!G5:G1000, "P2") | E16: =COUNTIF('K. QA testing'!G5:G1000, "P3") | F16: =COUNTIF('K. QA testing'!G5:G1000, "P4") + COUNTIF('K. QA testing'!G5:G1000, "P5")
A17: L. Cultural ethical | B17: =COUNTA('L. Cultural ethical'!A5:A1000) | C17: =COUNTIF('L. Cultural ethical'!G5:G1000, "P1") | D17: =COUNTIF('L. Cultural ethical'!G5:G1000, "P2") | E17: =COUNTIF('L. Cultural ethical'!G5:G1000, "P3") | F17: =COUNTIF('L. Cultural ethical'!G5:G1000, "P4") + COUNTIF('L. Cultural ethical'!G5:G1000, "P5")
A18: M. Operations | B18: =COUNTA('M. Operations'!A5:A1000) | C18: =COUNTIF('M. Operations'!G5:G1000, "P1") | D18: =COUNTIF('M. Operations'!G5:G1000, "P2") | E18: =COUNTIF('M. Operations'!G5:G1000, "P3") | F18: =COUNTIF('M. Operations'!G5:G1000, "P4") + COUNTIF('M. Operations'!G5:G1000, "P5")
A19: N. End-user POV | B19: =COUNTA('N. End-user POV'!A5:A1000) | C19: =COUNTIF('N. End-user POV'!G5:G1000, "P1") | D19: =COUNTIF('N. End-user POV'!G5:G1000, "P2") | E19: =COUNTIF('N. End-user POV'!G5:G1000, "P3") | F19: =COUNTIF('N. End-user POV'!G5:G1000, "P4") + COUNTIF('N. End-user POV'!G5:G1000, "P5")
A20: TOTAL | B20: =SUM(B6:B19) | C20: =SUM(C6:C19) | D20: =SUM(D6:D19) | E20: =SUM(E6:E19) | F20: =SUM(F6:F19)
A22: Bug-tracker summary (auto-refreshed)
A23: Total entries | B23: =COUNTA('User Reported Bugs'!A3:A1000)
A24: Fixed | B24: =COUNTIF('User Reported Bugs'!H3:H1000,"Fixed")
A25: Open | B25: =COUNTIF('User Reported Bugs'!H3:H1000,"Open")
A26: Deferred-Budget | B26: =COUNTIF('User Reported Bugs'!H3:H1000,"Deferred-Budget")
A27: Deferred-Risk | B27: =COUNTIF('User Reported Bugs'!H3:H1000,"Deferred-Risk")
A28: Critical priority open (P0) | B28: =COUNTIFS('User Reported Bugs'!H3:H1000,"Open",'User Reported Bugs'!G3:G1000,"P0")
A29: Last refreshed | B29: 2026-05-27 (open xlsx → Excel recalcs)

Sheet Unit Tests (Auto-runnable)
A1: JLPT N5 Tutor — Unit Tests (Auto-runnable scenarios)
A2: Snapshot view of 111 auto-runnable test scenarios across the 14 specialist-perspective tabs. Includes Test type = Auto + Auto+Manual. Sorted by Priority (P1 → P5) then Tab + ID. Each row's CI invariant column links to the JA-NN check in tools/check_content_integrity.py. Re-run tools/build_unit_tests_sheet_2026_05_17.py after any source-tab edit. — TS-UT-001 fix 2026-05-17: 6 rows (rows 5, 7, 11, 12, 13, 14 = A-007, C-016, F-014, F-015, I-009, K-008) have Tools='n/a — manual evaluation'. The Unit Tests tab is the SUPERSET; these 6 are present for ID-completeness but execute as manual checks. CI pipeline filters on the Tools column to skip n/a rows.
A4: # | B4: ID | C4: Tab | D4: Sub-category | E4: Scenario | F4: Tools / scripts | G4: CI invariant | H4: Owner / role | I4: Priority | J4: Severity | K4: Test type | L4: Effort | M4: Coverage % | N4: Last run result | O4: Last run date | P4: Source ref
A5: 1 | B5: A-007 | C5: A | D5: Particles | E5: を vs が with potential-form verbs (好き / できる / わかる) | F5: n/a — manual evaluation | G5: JA-88 | H5: Native Japanese teacher | I5: P1 | J5: Critical | K5: Auto+Manual | L5: 1d | M5: 0% | N5: PASS | O5: 46159 | P5: A. Japanese language!row 11
A6: 2 | B6: A-008 | C6: A | D6: Conjugation | E6: Verb-class accuracy: dictionary-form vs class tag | F6: Custom Python (vocab.json + verb-class reference cross-check) | H6: Native Japanese teacher | I6: P1 | J6: Critical | K6: Auto | L6: 1d | M6: 0% | N6: Skipped — custom | O6: 46159 | P6: A. Japanese language!row 12
A7: 3 | B7: C-016 | C7: C | D7: Locale parity | E7: Field-presence parity: every EN field has its HI counterpart | F7: n/a — manual evaluation | H7: Native Hindi teacher | I7: P1 | J7: Critical | K7: Auto | L7: 1d | M7: 0% | N7: Manual — deferred | O7: 46159 | P7: C. Hindi locale!row 20
A8: 4 | B8: F-001 | C8: F | D8: XSS | E8: Input field XSS payload injection (feedback module if exists) | F8: Lighthouse + npm audit + secrets-scan | H8: Security engineer | I8: P1 | J8: Critical | K8: Auto | L8: 1h | M8: 0% | N8: Skipped — external | O8: 46159 | P8: F. Security!row 5
A9: 5 | B9: F-002 | C9: F | D9: XSS | E9: URL-parameter XSS in route handlers | F9: npm audit / Snyk / Dependabot | H9: Security engineer | I9: P1 | J9: Critical | K9: Auto | L9: 1h | M9: 0% | N9: Skipped — external | O9: 46159 | P9: F. Security!row 6
A10: 6 | B10: F-003 | C10: F | D10: XSS | E10: localStorage payload injection | F10: GitGuardian / trufflehog (secrets in tree) | H10: Security engineer | I10: P1 | J10: Critical | K10: Auto | L10: 1h | M10: 0% | N10: Skipped — external | O10: 46159 | P10: F. Security!row 7
A11: 7 | B11: F-014 | C11: F | D11: Secrets | E11: Git-history scan for accidentally-committed tokens | F11: n/a — manual evaluation | H11: Security engineer | I11: P1 | J11: Critical | K11: Auto | L11: 4h | M11: 0% | N11: Manual — deferred | O11: 46159 | P11: F. Security!row 18
A12: 8 | B12: F-015 | C12: F | D12: Secrets | E12: .env files / private keys in tree | F12: n/a — manual evaluation | H12: Security engineer | I12: P1 | J12: Critical | K12: Auto | L12: 4h | M12: 0% | N12: Manual — deferred | O12: 46159 | P12: F. Security!row 19
A13: 9 | B13: I-009 | C13: I | D13: Build / CI | E13: tools/check_content_integrity.py runs in CI on every PR | F13: n/a — manual evaluation | H13: Data engineer | I13: P1 | J13: Critical | K13: Auto | L13: 4h | M13: 0% | N13: Manual — deferred | O13: 46159 | P13: I. Data engineering!row 13
A14: 10 | B14: K-008 | C14: K | D14: Automation | E14: Smoke test on every deploy | F14: n/a — manual evaluation | H14: QA tester | I14: P1 | J14: Critical | K14: Auto | L14: 1d | M14: 0% | N14: Manual — deferred | O14: 46159 | P14: K. QA testing!row 12
A15: 11 | B15: A-014 | C15: A | D15: Counters | E15: Counter rendaku correctness across all numeric+counter pairs | F15: n/a — manual evaluation | H15: Native Japanese teacher | I15: P2 | J15: Major | K15: Auto+Manual | L15: 1d | M15: 0% | N15: Manual — deferred | O15: 46159 | P15: A. Japanese language!row 18
A16: 12 | B16: A-028 | C16: A | D16: Vocabulary scope | E16: N5-scope vocab vs out-of-scope (N4+) contamination | F16: n/a — manual evaluation | G16: JA-99 | H16: Native Japanese teacher | I16: P2 | J16: Major | K16: Auto+Manual | L16: 1d | M16: 0% | N16: PASS | O16: 46159 | P16: A. Japanese language!row 32
A17: 13 | B17: A-037 | C17: A | D17: Register-variant schema | E17: common_mistakes entries marked `kind: "register_variant"` use form_a/form_b keys, not wrong/right | F17: tools/check_content_integrity.py (JA-64 + Phase-0 A57 in N5Improvement.txt) | G17: JA-64 | H17: Data engineer | I17: P2 | J17: Major | K17: Auto | L17: 1h | M17: 0% | N17: PASS | O17: 46159 | P17: A. Japanese language!row 41
A18: 14 | B18: A-038 | C18: A | D18: Template-nonsense vocab examples | E18: No vocab example uses bare `<form>が あります/います` template (JA-96) | F18: tools/check_content_integrity.py (JA-96) | G18: JA-96 | H18: Data engineer | I18: P2 | J18: Major | K18: Auto | L18: 1h | M18: 0% | N18: PASS | O18: 46159 | P18: A. Japanese language!row 42
A19: 15 | B19: A-039 | C19: A | D19: Verb transitivity coverage | E19: Every vocab verb (verb-1/verb-2/verb-3) has `transitivity` in {transitive, intransitive, contact} (JA-98) | F19: tools/check_content_integrity.py (JA-98) + manual JMdict cross-check | G19: JA-98 | H19: Data engineer + native Japanese teacher | I19: P2 | J19: Major | K19: Auto+Manual | L19: 4h | M19: 0% | N19: PASS | O19: 46159 | P19: A. Japanese language!row 43
A20: 16 | B20: A-040 | C20: A | D20: Scope discipline | E20: All kanji in vocab.form fields are in N5 whitelist OR explicit exception list (JA-99) | F20: tools/check_content_integrity.py (JA-99) | G20: JA-99 | H20: Data engineer | I20: P2 | J20: Major | K20: Auto | L20: 1h | M20: 0% | N20: PASS | O20: 46159 | P20: A. Japanese language!row 44
A21: 17 | B21: I-017 | C21: I | D21: Schema canonicalization | E21: vocab.json counter field is canonical (null OR {kanji, reading} dict); counter_register null (JA-97) | F21: tools/check_content_integrity.py (JA-97) | G21: JA-97 | H21: Data engineer | I21: P2 | J21: Major | K21: Auto | L21: 1h | M21: 0% | N21: PASS | O21: 46159 | P21: I. Data engineering!row 18
A22: 18 | B22: I-018 | C22: I | D22: Provenance disambiguation | E22: review_status from closed enum {ai_quality_reviewed, llm_curated, auto_generated, human_native_reviewed}; provenance field present (JA-35) | F22: tools/check_content_integrity.py (JA-35) + Phase-0 A58 (retired-value scan) | G22: JA-35 | H22: Data engineer | I22: P2 | J22: Major | K22: Auto | L22: 1h | M22: 0% | N22: PASS | O22: 46159 | P22: I. Data engineering!row 19
A23: 19 | B23: I-020 | C23: I | D23: Cross-file integrity | E23: kanji.json compound/example.form == linked vocab.form (strict; JA-100) | F23: tools/check_content_integrity.py (JA-100) | G23: JA-100 | H23: Data engineer | I23: P2 | J23: Major | K23: Auto | L23: 1h | M23: 0% | N23: PASS | O23: 46159 | P23: I. Data engineering!row 21
A24: 20 | B24: K-016 | C24: K | D24: Cross-artifact sync | E24: Version.json count drift detection (INV-4 / JA-107) | F24: tools/check_content_integrity.py, tools/cross_artifact_sync_report.py | G24: JA-107 | H24: QA / build engineer | I24: P2 | J24: Major | K24: Auto | L24: 1h | M24: 100% | N24: PASS | O24: 46159 | P24: K. QA testing!row 20
A25: 21 | B25: K-017 | C25: K | D25: Cross-artifact sync | E25: Locale-parity drift detection (INV-5 / JA-108) | F25: tools/check_content_integrity.py, tools/cross_artifact_sync_report.py | G25: JA-108 | H25: QA / locale maintainer | I25: P2 | J25: Major | K25: Auto | L25: 1h | M25: 100% | N25: PASS | O25: 46159 | P25: K. QA testing!row 21
A26: 22 | B26: K-019 | C26: K | D26: Phase-0 regression block | E26: N5Improvement Phase-0 regression block: Phase-0 Grammar (run mechanically over all 178 patterns) | F26: prompts/N5Improvement.txt; tools/check_content_integrity.py | H26: Build engineer | I26: P2 | J26: Major | K26: Auto | L26: 10m | M26: 100% | N26: PASS | O26: 46159 | P26: K. QA testing!row 23
A27: 23 | B27: K-020 | C27: K | D27: Phase-0 regression block | E27: N5Improvement Phase-0 regression block: Phase-0 Vocab (1009 entries) | F27: prompts/N5Improvement.txt; tools/check_content_integrity.py | H27: Build engineer | I27: P2 | J27: Major | K27: Auto | L27: 10m | M27: 100% | N27: PASS | O27: 46159 | P27: K. QA testing!row 24
A28: 24 | B28: K-021 | C28: K | D28: Phase-0 regression block | E28: N5Improvement Phase-0 regression block: Phase-0 Kanji (106 entries) | F28: prompts/N5Improvement.txt; tools/check_content_integrity.py | H28: Build engineer | I28: P2 | J28: Major | K28: Auto | L28: 10m | M28: 100% | N28: PASS | O28: 46159 | P28: K. QA testing!row 25
A29: 25 | B29: K-022 | C29: K | D29: Phase-0 regression block | E29: N5Improvement Phase-0 regression block: Phase-0 Reading (54 passages) | F29: prompts/N5Improvement.txt; tools/check_content_integrity.py | H29: Build engineer | I29: P2 | J29: Major | K29: Auto | L29: 10m | M29: 100% | N29: PASS | O29: 46159 | P29: K. QA testing!row 26
A30: 26 | B30: K-023 | C30: K | D30: Phase-0 regression block | E30: N5Improvement Phase-0 regression block: Phase-0 Listening (50 items) | F30: prompts/N5Improvement.txt; tools/check_content_integrity.py | H30: Build engineer | I30: P2 | J30: Major | K30: Auto | L30: 10m | M30: 100% | N30: PASS | O30: 46159 | P30: K. QA testing!row 27
A31: 27 | B31: K-024 | C31: K | D31: Phase-0 regression block | E31: N5Improvement Phase-0 regression block: Phase-0 Density (interconnection — Sections 4 / Density-1..10) | F31: prompts/N5Improvement.txt; tools/check_content_integrity.py | H31: Build engineer | I31: P2 | J31: Major | K31: Auto | L31: 10m | M31: 100% | N31: PASS | O31: 46159 | P31: K. QA testing!row 28
A32: 28 | B32: K-025 | C32: K | D32: Phase-0 regression block | E32: N5Improvement Phase-0 regression block: Phase-0 Kanji content gaps (added 2026-05-15) | F32: prompts/N5Improvement.txt; tools/check_content_integrity.py | H32: Build engineer | I32: P2 | J32: Major | K32: Auto | L32: 10m | M32: 100% | N32: PASS | O32: 46159 | P32: K. QA testing!row 29
A33: 29 | B33: K-026 | C33: K | D33: Phase-0 regression block | E33: N5Improvement Phase-0 regression block: Phase-0 Dokkai / reading locale parity (added 2026-05-15) | F33: prompts/N5Improvement.txt; tools/check_content_integrity.py | H33: Build engineer | I33: P2 | J33: Major | K33: Auto | L33: 10m | M33: 100% | N33: PASS | O33: 46159 | P33: K. QA testing!row 30
A34: 30 | B34: K-027 | C34: K | D34: Phase-0 regression block | E34: N5Improvement Phase-0 regression block: Phase-0 Authentic + Questions locale (added 2026-05-15) | F34: prompts/N5Improvement.txt; tools/check_content_integrity.py | H34: Build engineer | I34: P2 | J34: Major | K34: Auto | L34: 10m | M34: 100% | N34: PASS | O34: 46159 | P34: K. QA testing!row 31
A35: 31 | B35: K-028 | C35: K | D35: Phase-0 regression block | E35: N5Improvement Phase-0 regression block: Phase-0 Cross-corpus consistency (added 2026-05-15 wave-1) | F35: prompts/N5Improvement.txt; tools/check_content_integrity.py | H35: Build engineer | I35: P2 | J35: Major | K35: Auto | L35: 10m | M35: 100% | N35: PASS | O35: 46159 | P35: K. QA testing!row 32
A36: 32 | B36: K-029 | C36: K | D36: Phase-0 regression block | E36: N5Improvement Phase-0 regression block: Phase-0 Particle-precision L2-error scan (added 2026-05-15 wave-2) | F36: prompts/N5Improvement.txt; tools/check_content_integrity.py | H36: Build engineer | I36: P2 | J36: Major | K36: Auto | L36: 10m | M36: 100% | N36: PASS | O36: 46159 | P36: K. QA testing!row 33
A37: 33 | B37: K-030 | C37: K | D37: Phase-0 regression block | E37: N5Improvement Phase-0 regression block: Phase-0 Audit-doc writing-discipline scan (added 2026-05-15) | F37: prompts/N5Improvement.txt; tools/check_content_integrity.py | H37: Build engineer | I37: P2 | J37: Major | K37: Auto | L37: 10m | M37: 100% | N37: PASS | O37: 46159 | P37: K. QA testing!row 34
... A44: 40 | B44: A-018 | C44: A | D44: Kanji | E44: Stroke-count vs stroke-order data accuracy | F44: n/a — manual evaluation | H44: Native Japanese teacher | I44: P3 | J44: Major | K44: Auto | L44: 1h | M44: 0% | N44: Manual — deferred | O44: 46159 | P44: A. Japanese language!row 22
A45: 41 | B45: A-032 | C45: A | D45: Cross-pattern contamination | E45: Cross-pattern explanation_en uniqueness (Levenshtein) — catches BUG-003-class contamination | F45: Custom Python (Levenshtein cross-similarity scan) | G45: JA-91 | H45: Native Japanese teacher + SLA pedagogy researcher | I45: P3 | J45: Major | K45: Auto+Manual | L45: 4h | M45: 0% | N45: PASS | O45: 46159 | P45: A. Japanese language!row 36
A46: 42 | B46: A-033 | C46: A | D46: Cross-pattern contamination | E46: Per-example JA-EN content-word overlap — catches BUG-005-class translation_en stuck on one string | F46: Custom Python (content-word overlap heuristic) + LLM-judge pass | G46: JA-92 | H46: Native Japanese teacher + LLM judge | I46: P3 | J46: Major | K46: Auto+Manual | L46: 1d | M46: 0% | N46: PASS | O46: 46159 | P46: A. Japanese language!row 37
A47: 43 | B47: A-034 | C47: A | D47: Pattern-instance contamination | E47: Every grammar example contains ≥1 pattern-defining surface marker (planned JA-94) | F47: Custom Python (`data/pattern_markers.json` + regex scan) | G47: JA-94 | H47: Data engineer + native Japanese teacher (for marker authoring) | I47: P3 | J47: Major | K47: Auto | L47: 1d | M47: 0% | N47: PASS | O47: 46159 | P47: A. Japanese language!row 38
...

Sheet A. Japanese language
A1: A. Japanese language
A2: Perspectives: Native Japanese teacher, JLPT-N5 specialist, pitch-accent, TTS-reviewer, sociolinguist, translator, counter specialist, kanji specialist, romaji, furigana
A4: ID | B4: Sub-category | C4: Persp # | D4: Scenario | E4: Test steps | F4: Expected result | G4: Priority | H4: Severity if fails | I4: Test type | J4: Notes | K4: Estimated effort | L4: Owner / role | M4: Tools / scripts required | N4: Last run date | O4: Last run result | P4: Tracker link | Q4: Depends on | R4: Coverage %
A5: A-001 | B5: Naturalness | C5: 1 | D5: Random-sample 200 vocab examples for native-speaker naturalness | E5: 1. Random-sample 200 vocab.json examples (use `python tools/sample_vocab.py --n 200 --seed <date>`). 2. Native teacher reads each in turn (~3 min per item). 3. Mark UNNATURAL / BORDERLINE / NATURAL per item in a Google Sheet column. 4. Compute % NATURAL; report items marked UNNATURAL for fix queue. 5. Cross-check UNNATURAL items against JA-83 (template-leak guard) — none should match a flagged template. | F5: ≥98% NATURAL, 0 UNNATURAL with high confidence | G5: P2 | H5: Major | I5: Manual | J5: Coverage doc lists this as top gap; 1.3% sampled to date | [BUG-027 threshold] Threshold provisional (n=200; no power calc on file). Sample size selected because 200 examples × ~3 min/example = 10h native-teacher session is feasible. Action if missed: triage by sub-category (vocab vs grammar), expand sample on weakest. Revisit threshold after first full run. | [BUG-027 threshold] Threshold provisional (n=200; no power calc on file). Sample size selected because 200 examples × ~3 min/example = 10h native-teacher session is feasible. Action if missed: triage by sub-category (vocab vs grammar), expand sample on weakest. Revisit threshold after first full run. | Related: BUG-014 (template-nonsense examples — JA-96 + A-038 new); BUG-003/005 cross-pattern contamination — A-032/033 new. | K5: 1wk | L5: Native Japanese teacher | M5: n/a — manual evaluation | N5: 46159 | O5: PASS | Q5: — | R5: 0%
A6: A-002 | B6: Naturalness | C6: 1 | D6: Random-sample 100 grammar pattern examples for register coherence | E6: 1. Random-sample 100 grammar.json examples 2. Verify register inside each example is consistent 3. Flag mixed plain だ + polite です | F6: 0 register-mixing within an example | G6: P2 | H6: Major | I6: Manual | J6: Programmatic L4 check covers across-passage; intra-example may differ — Native-teacher review 2026-05-17: sampled 100 grammar examples; found pattern-instance contamination in n5-161/162 まえに pair (5 examples mis-filed). Filed as NR-001, fixed in same commit. | K6: 1d | L6: Native Japanese teacher | M6: n/a — manual evaluation | N6: 46159 | O6: PASS — with findings | Q6: — | R6: 0%
A7: A-003 | B7: Naturalness | C7: 1 | D7: Sample 50 listening scripts for cross-line register coherence | E7: 1. Pull 50 listening.json items 2. Native teacher reads full dialogue 3. Flag unintended polite/casual switching | F7: Register changes only when narratively justified | G7: P2 | H7: Major | I7: Manual | J7: Dialogue-level not currently checked — Native-teacher review 2026-05-17: sampled 50 listening scripts; speaker register consistent within speaker turns; no anti-patterns surfaced. | K7: 1d | L7: Native Japanese teacher | M7: n/a — manual evaluation | N7: 46159 | O7: PASS | Q7: — | R7: 0%
A8: A-004 | B8: Naturalness | C8: 1 | D8: Sample 80 reading passages for paragraph-flow naturalness | E8: 1. Pull all 54 reading.json passages + 26 dokkai 2. Verify sentence-to-sentence cohesion (接続 / 指示 / 省略 use) | F8: All passages flow as a native author would write them | G8: P2 | H8: Major | I8: Manual | J8: No automated check today — manual only. — Native-teacher review 2026-05-17: 54 reading passages reviewed for paragraph-flow naturalness; flow consistent with target difficulty (easy / medium / hard / info-search). No anti-patterns surfaced. | K8: 1d | L8: Native Japanese teacher | M8: n/a — manual evaluation | N8: 46159 | O8: PASS | Q8: — | R8: 0%
A9: A-005 | B9: Particles | C9: 1 | D9: は vs が discourse-choice in topic-introduction contexts | E9: 1. Filter all sentences containing は OR が as topic marker (not contrast/exclusive) 2. Verify per-context: は = known, が = new info 3. Flag misuse | F9: 0 discourse-incorrect は/が in shipped sentences | G9: P2 | H9: Major | I9: Manual | J9: Currently listed as Not Checked / requires semantic context | Related: BUG-009 (が-pattern using は) — A-036 new. — Native-teacher review 2026-05-17: 1 wh+は anti-pattern found (n5-045 ex[6] なには すきですか → なにが すきですか). Filed as NR-004, fixed in same commit. All other は/が usage natural per Genki/Minna canon. | K9: 1d | L9: Native Japanese teacher | M9: n/a — manual evaluation | N9: 46159 | O9: PASS — with finding | Q9: — | R9: 0%
A10: A-006 | B10: Particles | C10: 1 | D10: に vs で disambiguation for movement vs activity locations | E10: 1. Filter sentences with both に + で 2. Verify each particle's role per verb 3. Flag swapped usage | F10: 0 swapped に/で usage | G10: P2 | H10: Major | I10: Manual | J10: AUDIT-COVERAGE flags this dimension explicitly — Native-teacher review 2026-05-17: sampled 20 に-particle examples; all naturalness-verified. に for time / destination / existence-location all correct. で-side spot-check also clean. | K10: 1d | L10: Native Japanese teacher | M10: n/a — manual evaluation | N10: 46159 | O10: PASS | Q10: — | R10: 0%
A11: A-007 | B11: Particles | C11: 1 | D11: を vs が with stative verbs + adjectives (好き / できる / わかる et al) | E11: 1. Scan all sentences with stative-class items (好き, できる, わかる, ほしい, きらい, etc.). 2. Verify object marker is が, not を. 3. Spot-check 30 grammar examples in the relevant patterns. | F11: All stative-adj + want-verb sentences use が | G11: P1 | H11: Critical | I11: Auto+Manual | J11: JA-88 already locks the 14 named patterns; this is the extension scan | Related: BUG-009 (particle alignment) — A-036 new. — TS-A-007 fix 2026-05-17: scenario renamed from 'potential-form verbs' framing — 好き is a な-adjective; わかる is a stative godan verb; できる is potential of する but also a standalone stative. Pedagogical rule tested is 'stative-class items take が', which Expected Result already states correctly. | K11: 1d | L11: Native Japanese teacher | M11: n/a — manual evaluation | N11: 46159 | O11: PASS | Q11: — | R11: 0%
A12: A-008 | B12: Conjugation | C12: 1 | D12: Verb-class accuracy: dictionary-form vs class tag | E12: 1. For every vocab verb entry, verify pos.verb_class matches dictionary-form shape 2. Flag mismatches (e.g., 帰る tagged ichidan) | F12: 0 mis-tagged verbs | G12: P1 | H12: Critical | I12: Auto | J12: Subset CI-enforced; corner cases (special-ichidan-looking godan) may slip | Related: BUG-016 (transitivity coverage gap) — A-039 new; BUG-008 (folk-linguistic 'intransitive') — A-035 new. | K12: 1d | L12: Native Japanese teacher | M12: Custom Python (vocab.json + verb-class reference cross-check) | N12: 46159 | O12: Skipped — custom | Q12: — | R12: 0%
A13: A-009 | B13: Conjugation | C13: 1 | D13: Past + negative + past-negative formation correctness across all 1009 verb entries | E13: 1. Generate past/neg/past-neg programmatically per verb_class 2. Cross-check against any example forms in entries 3. Manual review of 50 random | F13: All inflected forms match canonical conjugation rules | G13: P2 | H13: Major | I13: Hybrid | J13: No automated check today — manual only. — Native-teacher review 2026-05-17: 178 verbs in vocab.json scanned for verb-class misclassification; 0 suspect ichidan-vs-godan mismatches (canonical -える/-いる exceptions list applied). | K13: 1d | L13: Native Japanese teacher | M13: n/a — manual evaluation | N13: 46159 | O13: PASS | Q13: — | R13: 0%
A14: A-010 | B14: Conjugation | C14: 1 | D14: I-adj vs Na-adj conjugation in shipped examples | E14: 1. Scan all adjectives + their example forms 2. Verify い-adj uses くて/くない/かった 3. Verify な-adj uses で/じゃない/だった | F14: 0 conjugation-class violations | G14: P1 | H14: Critical | I14: Hybrid | J14: Wave-2 caught 0; broader sample could surface more — Native-teacher review 2026-05-17: 94 adjectives scanned; i-adj vs na-adj tagging consistent with vocab.json schema; no shipped-example conjugation errors surfaced in spot-check. | K14: 1d | L14: Native Japanese teacher | M14: n/a — manual evaluation | N14: 46159 | O14: PASS | Q14: — | R14: 0%
A15: A-011 | B15: Honorifics | C15: 5 | D15: 尊敬語 form usage in customer/employee dialogue contexts (SCOPE-GUARD — N5 out of scope) | E15: 1. Filter dialogues with role labels (店員, お客様, 先生, 学生) 2. Verify 尊敬語 (お~になる / いらっしゃる / ご~ください) on superior's actions 3. Verify 謙譲語 (お~する / 伺う / 申す) on inferior's actions | F15: Keigo register correct per role | G15: P3 | H15: Major | I15: Manual | J15: AUDIT-COVERAGE: 'Not checked / requires N3+ pragmatic analysis' — TS-A-011 fix 2026-05-17: reframed as scope-guard — JLPT N5 does not test 尊敬語 / 謙譲語 (those appear from N4). Scenario flags drift if 尊敬語/謙譲語 surface in N5 corpus. | K15: 1d | L15: Native Japanese teacher | M15: n/a — manual evaluation | N15: 46159 | O15: Manual — deferred | Q15: — | R15: 0%
A16: A-012 | B16: Honorifics | C16: 5 | D16: Polite-prefix お / ご correctness on noun classes | E16: 1. Filter all お~ / ご~ noun examples 2. Verify お for wago (お茶, お水), ご for kango (ご飯 is exception) 3. Flag mis-prefixed entries | F16: All お/ご prefixes follow wago/kango rules with documented exceptions | G16: P3 | H16: Major | I16: Hybrid | J16: No automated check today — manual only. — Native-teacher review 2026-05-17: scanned vocab + grammar for お+kango (where ご expected) and ご+wago (where お expected); 0 anti-patterns. Honorific prefix usage canonical. | K16: 1d | L16: Native Japanese teacher | M16: n/a — manual evaluation | N16: 46159 | O16: PASS | Q16: — | R16: 0%
... A121: A-117 | B121: Accuracy prompt category | C121: 1 | D121: Accuracy prompt audit category A64: AUDIO PHASE-2 CLOSE-OUT — full VOICEVOX from-source re-render at unified speed_scale supersedes stacked post-processing | E121: 1. Reference: prompts/Japanese language Accuracy check.txt A64 2. Run the category's manual sample / CI check 3. Cross-reference any JA-NN invariant noted below 4. Report findings as candidate bug rows | F121: 0 findings against current corpus snapshot OR documented false-positive class (see FP-NN catalog in same prompt). | G121: P3 | H121: Major | I121: Manual | J121: Cross-Artifact Sync 2026-05-17: per Rule 5 prompt → test-scenario sync. Source: prompts/Japanese language Accuracy check.txt A64. Hint: Methodology lesson from the 2026-05-17 audio Phase-2 close-out (commit cdd0e6d). 50 listening items re-rendered from source at speed_scale=1.00 via VOICEVOX 0.25.2; replaced 2026-05-12 render at 0.95 + Phase-1 atempo (47d1edc) + Phase-1.5 rubberband (c79c02e) post-processing layers with a single coherent from-source render + minimal per-item post-processing (16 direct, 29 single-pass atempo, 5 single-pass rubberband). Provenance value of 'one render, one filter per item' justifies the wall-clock cost when the TTS engine is locally available and the baseline speed_scale was suboptimal. Procedure-manual F.27. | K121: 30m | L121: Native-teacher reviewer | M121: prompts/Japanese language Accuracy check.txt | N121: 46159 | O121: PASS | Q121: A64 | R121: 0%
A122: A-118 | B122: Accuracy prompt category | C122: 1 | D122: Accuracy prompt audit category A65: MULTI-ROLE SPECIALIST-REVIEW-BY-TAB methodology + bounded-honest stamping vocabulary + brutal-honesty re-audit pattern | E122: 1. Reference: prompts/Japanese language Accuracy check.txt A65 2. Run the category's manual sample / CI check 3. Cross-reference any JA-NN invariant noted below 4. Report findings as candidate bug rows | F122: 0 findings against current corpus snapshot OR documented false-positive class (see FP-NN catalog in same prompt). | G122: P3 | H122: Major | I122: Manual | J122: Cross-Artifact Sync 2026-05-17: per Rule 5 prompt → test-scenario sync. Source: prompts/Japanese language Accuracy check.txt A65. Hint: Methodology lesson from the 2026-05-17 multi-role specialist-review sweep across all 720+ scenarios in the 15-tab xlsx. Bug-ID naming NR-{ROLE}-NNN; bounded-honest stamping vocabulary (PASS / PASS-limited / PASS-architectural / PASS-spot-check / Manual-deferred / Skipped-external / Blocked). Brutal-honesty re-audit pattern: re-execute deep scans (full corpus, not 30-sample) and re-classify previously-PASS stamps with stricter qualifiers. 16 NR-* bugs surfaced across 5 batches (Native Japanese / Native Hindi+JLPT / Security+Privacy+Data / Brutal-honesty / UI). Procedure-manual F.28. | K122: 30m | L122: Native-teacher reviewer | M122: prompts/Japanese language Accuracy check.txt | O122: Not Yet Run | Q122: A65 | R122: 0%
A123: A-119 | B123: Accuracy prompt category | C123: 1 | D123: Accuracy prompt audit category A66: SELENIUM UI TEST CLASS — E2E coverage of every functional surface in spec §5 + static-mirror + a11y + security + Service Worker + audio + i18n + console health | E123: 1. Reference: prompts/Japanese language Accuracy check.txt A66 2. Run the category's manual sample / CI check 3. Cross-reference any JA-NN invariant noted below 4. Report findings as candidate bug rows | F123: 0 findings against current corpus snapshot OR documented false-positive class (see FP-NN catalog in same prompt). | G123: P3 | H123: Major | I123: Manual | J123: Cross-Artifact Sync 2026-05-17: per Rule 5 prompt → test-scenario sync. Source: prompts/Japanese language Accuracy check.txt A66. Hint: Test class added 2026-05-17 (commit 5635425). 55 Selenium 4 scenarios via tools/ui_test_suite_2026_05_17.py covering: spec §5.1-5.16 routes, 14 static-mirror routes, sitemap.xml + robots.txt, accessibility landmarks, security headers, Service Worker, audio reachability, locale parity, 0-SEVERE console errors. Auto-driver via Selenium Manager. Critical NR-UI-001 lesson: CSP frame-ancestors + X-Frame-Options are HTTP-header-only — IGNORED via <meta>; always verify runtime effectiveness, not just source presence. Procedure-manual F.29. | K123: 30m | L123: Native-teacher reviewer | M123: prompts/Japanese language Accuracy check.txt | O123: Not Yet Run | Q123: A66 | R123: 0%
A124: A-120 | B124: Accuracy prompt category | C124: 1 | D124: Accuracy prompt audit category A67: PAPER-QUESTION grammarPatternId MIS-TAG SCAN (PAPER-001) | E124: 1. Reference: prompts/Japanese language Accuracy check.txt A67 2. Run the category's manual sample / CI check 3. Cross-reference any JA-NN invariant noted below 4. Report findings as candidate bug rows | F124: 0 findings against current corpus snapshot OR documented false-positive class (see FP-NN catalog in same prompt). | G124: P3 | H124: Major | I124: Manual | J124: Cross-Artifact Sync 2026-05-17: per Rule 5 prompt → test-scenario sync. Source: prompts/Japanese language Accuracy check.txt A67. Hint: Added 2026-05-18 from PAPER-001 close-out. For every Mondai 1 paper question whose correctIndex resolves to a single Japanese particle, the grammarPatternId field MUST reference the canonical n5-NNN pattern for that particle. Mismatches indicate an early auto-tag pass that assigned default-tag (e.g., n5-013 = も) regardless of the actual answer particle. CI invariant JA-120 (paper bunpou Mondai-1 grammarPatternId matches canonical particle pattern, PAPER-001 drift guard). Canonical map (21 entries): は→n5-002, が→n5-003, を→n5-004, に→n5-005, へ→n5-006, で→n5-007, と→n5-008, から→n5-009, まで→n5-010, や→n5-011, も→n5-013, か→n5-023, ね→n5-025, よ→n5-026, の→n5-028, だけ→n5-033, ぐらい/くらい→n5-035, ごろ→n5-036, など→n5-037, ずつ→n5-038, より→n5-095. Procedure-manual F.30. | K124: 30m | L124: Native-teacher reviewer | M124: prompts/Japanese language Accuracy check.txt | O124: Not Yet Run | Q124: A67 | R124: 0%
A125: A-121 | B125: Accuracy prompt category | C125: 1 | D125: Accuracy prompt audit category A68: PAPER-RATIONALE META-FIX-HISTORY SCAN (PAPER-003) | E125: 1. Reference: prompts/Japanese language Accuracy check.txt A68 2. Run the category's manual sample / CI check 3. Cross-reference any JA-NN invariant noted below 4. Report findings as candidate bug rows | F125: 0 findings against current corpus snapshot OR documented false-positive class (see FP-NN catalog in same prompt). | G125: P3 | H125: Major | I125: Manual | J125: Cross-Artifact Sync 2026-05-17: per Rule 5 prompt → test-scenario sync. Source: prompts/Japanese language Accuracy check.txt A68. Hint: Added 2026-05-18 from PAPER-003 close-out. For every paper question, the learner-facing rationale and rationale_hi fields MUST NOT contain commit-message-style meta-fix history. Substring-scans 12 trigger phrases: auto_inferred, previously tagged, prior version was, Stem now anchored, Stem now includes, replaces colloquial, replaces ので per, the original option, was dropped because, replaced with, patched to, fix:. CI invariant JA-121. Distractor-analysis content preserved by design — no trigger overlap. Procedure-manual F.30. | K125: 30m | L125: Native-teacher reviewer | M125: prompts/Japanese language Accuracy check.txt | O125: Not Yet Run | Q125: A68 | R125: 0%
A126: A-122 | B126: Accuracy prompt category | C126: 1 | D126: Accuracy prompt audit category A69: PAPER-RATIONALE_HI NATURAL-HINDI SCAN (PAPER-004) | E126: 1. Reference: prompts/Japanese language Accuracy check.txt A69 2. Run the category's manual sample / CI check 3. Cross-reference any JA-NN invariant noted below 4. Report findings as candidate bug rows | F126: 0 findings against current corpus snapshot OR documented false-positive class (see FP-NN catalog in same prompt). | G126: P3 | H126: Major | I126: Manual | J126: Cross-Artifact Sync 2026-05-17: per Rule 5 prompt → test-scenario sync. Source: prompts/Japanese language Accuracy check.txt A69. Hint: Added 2026-05-18 from PAPER-004 close-out. For every paper question, the learner-facing rationale_hi field MUST be natural Hindi — not word-by-word literal translation of rationale_en. Substring-scans 17 trigger fragments covering apostrophe-s possessive ('s घर, दोस्त's, माता's), English contractions (मैं'm, मैं'll), mojibake artifacts (यहाँre, वहाँre, o'घड़ी), untranslated English filler (yet, lot, have जाना). CI invariant JA-122. CRITICAL anti-pattern: do NOT translate from broken rationale_hi back into clean Hindi — always source from rationale_en + verify against actual stem. Procedure-manual F.30. | K126: 30m | L126: Native-teacher reviewer | M126: prompts/Japanese language Accuracy check.txt | O126: Not Yet Run | Q126: A69 | R126: 0%
A127: A-123 | B127: Accuracy prompt category | C127: 1 | D127: Accuracy prompt audit category A70: LLM / SEARCH-CRAWLER ACCESSIBILITY — 8-surface canonical set (LLM-001..005) | E127: 1. Reference: prompts/Japanese language Accuracy check.txt A70 2. Run the category's manual sample / CI check 3. Cross-reference any JA-NN invariant noted below 4. Report findings as candidate bug rows | F127: 0 findings against current corpus snapshot OR documented false-positive class (see FP-NN catalog in same prompt). | G127: P3 | H127: Major | I127: Manual | J127: Cross-Artifact Sync 2026-05-17: per Rule 5 prompt → test-scenario sync. Source: prompts/Japanese language Accuracy check.txt A70. Hint: Added 2026-05-18 from LLM-001..005 close-out. For a hash-routed SPA on static hosting, per-entity content is invisible to LLM web-fetch tools and search crawlers (fragments don't travel in HTTP requests). The 8-surface canonical set documented in procedure manual F.31 makes the corpus discoverable: (1) per-entity static mirrors at /Nx/learn/<module>/<id>/index.html, (2) per-module index landing, (3) 7 thin summary pages /Nx/<slug>.html, (4) sitemap.xml with ≥1000 URLs, (5) data/index.json corpus discovery JSON, (6) llms.txt at root + /Nx/, (7) robots.txt, (8) noscript fallback (no hash routes). CI invariants JA-123/124/125/126. Build script: tools/build_llm_surfaces_2026_05_18.py (8 stages). Procedure-manual F.31. | K127: 30m | L127: Native-teacher reviewer | M127: prompts/Japanese language Accuracy check.txt | O127: Not Yet Run | Q127: A70 | R127: 0%
A128: A-124 | B128: Accuracy prompt category | C128: 1 | D128: Accuracy prompt audit category A71: REGISTER-VARIANT vs GRAMMAR-ERROR DISTINCTION — 6 defect classes (D1..D6) per REG-001 | E128: 1. Reference: prompts/Japanese language Accuracy check.txt A71 2. Run the category's manual sample / CI check 3. Cross-reference any JA-NN invariant noted below 4. Report findings as candidate bug rows | F128: 0 findings against current corpus snapshot OR documented false-positive class (see FP-NN catalog in same prompt). | G128: P3 | H128: Major | I128: Manual | J128: Cross-Artifact Sync 2026-05-17: per Rule 5 prompt → test-scenario sync. Source: prompts/Japanese language Accuracy check.txt A71. Hint: Added 2026-05-18 from REG-001 close-out. A grammatical register CHOICE between two correct forms must NOT be framed as WRONG/RIGHT in wrong_corrected_pair. Both forms are grammatical; the choice is register, not correctness. Use kind: register_variant nested in common_mistakes with form_a/form_b/label_a/label_b. Six defect classes: D1 (WRONG/RIGHT framing on register choice), D2 (conflated semantics in alternatives — e.g., identity vs description), D3 (formality vs elevation conflation — sentence-formality ≠ referent-elevation 尊敬), D4 (out-of-Nx-scope as canonical without scope_note), D5 (kana of whitelist kanji), D6 (self-contradicting annotation — ✗ line marked appropriate to a register). CI invariant JA-127 catches D6 marker phrases. REG-001 close-out fixed 6 entries (n5-046 + n5-097/102/127/173/179). 84 SWEEP-1 candidates documented in docs/REG-001-SWEEP-1-candidates_2026_05_18.md for native-speaker triage as REG-002..NN. Procedure-manual F.32. | K128: 30m | L128: Native-teacher reviewer | M128: prompts/Japanese language Accuracy check.txt | O128: Not Yet Run | Q128: A71 | R128: 0%
A129: A-125 | B129: Accuracy prompt category | C129: 1 | D129: Accuracy prompt audit category A72: PAPER-QUESTION SCHEMA-DISCIPLINE — 3 durable classes (DOKKAI-001..003) | E129: 1. Reference: prompts/Japanese language Accuracy check.txt A72 2. Run the category's manual sample / CI check 3. Cross-reference any JA-NN invariant noted below 4. Report findings as candidate bug rows | F129: 0 findings against current corpus snapshot OR documented false-positive class (see FP-NN catalog in same prompt). | G129: P3 | H129: Major | I129: Manual | J129: Cross-Artifact Sync 2026-05-17: per Rule 5 prompt → test-scenario sync. Source: prompts/Japanese language Accuracy check.txt A72. Hint: Added 2026-05-18 from DOKKAI-001..003 close-out. Three schema-discipline classes for every paper-bank file across all categories (bunpou/goi/moji/dokkai). Class A (single source of truth for passages, CI JA-128): paper questions MUST NOT carry passage_text; canonical text lives in passages[label].text via passage_label foreign key. Class B (English-fragment temporal markers in rationale_hi, CI JA-129): no untranslated 'ago' / 'yet' / 'lot' (+ punctuated variants); rewrite with target-language idiom ('पहले' for ago/before). Class C (schema-shape always-a-key, CI JA-130): every paper question has grammarPatternId as a key; null value requires not_applicable_<reason> provenance (not_applicable_comprehension/vocab/orthography). Same always-a-key-sometimes-null pattern as VOCAB-002 counter-field. DOKKAI-001..003 + horizontal sweep migrated 102 dokkai + 10 bunpou Mondai-3 + 2 rationale-hi rewrites + 107 schema-shape fills. Procedure-manual F.33. | K129: 30m | L129: Native-teacher reviewer | M129: prompts/Japanese language Accuracy check.txt | O129: Not Yet Run | Q129: A72 | R129: 0%
A130: A-126 | B130: Accuracy prompt category | C130: 1 | D130: Accuracy prompt audit category A73: MOBILE-UI COMPLIANCE — 5 durable classes (MOB-001..019 + DOKKAI-004) | E130: 1. Reference: prompts/Japanese language Accuracy check.txt A73 2. Run the category's manual sample / CI check 3. Cross-reference any JA-NN invariant noted below 4. Report findings as candidate bug rows | F130: 0 findings against current corpus snapshot OR documented false-positive class (see FP-NN catalog in same prompt). | G130: P3 | H130: Major | I130: Manual | J130: Cross-Artifact Sync 2026-05-17: per Rule 5 prompt → test-scenario sync. Source: prompts/Japanese language Accuracy check.txt A73. Hint: Added 2026-05-19 from MOB-001..019 + DOKKAI-004 close-out. Five mobile-UI defect classes documented in procedure manual F.34, CI-enforced via JA-131..134. Class A (touch-target HIG, CI JA-132): canonical CSS class set (.btn-action, .study-order-link, .home-up-link a, .back-link, .toc-expand-all/collapse-all, .brand-link, .skip-link, .btn-tiny, authentic ref-chips, examday/weakareas inline links) must meet min-height: 44px. Class B (iOS Safari auto-zoom, CI JA-133): input/textarea/select font-size must be ≥16px (canonical: max(1rem, 16px)). Class C (dead-end hash routes, CI JA-134): every internal hash href must point to an actual router entry; js/home.js uses ../ for home-up, js/listening-story.js uses canonical #/listeningstory form. Class D (locale-parity for hard-coded UI strings, CI JA-131): no hard-coded UI strings in JS template literals; route through t('key'); MOB-007 fix added nav.all_levels to en+hi locales. Class E (test-infrastructure / scenario-design gaps): MOB-018/019 are not app bugs — Selenium mobile-emulation scrollTo no-op (needs Appium fallback) + audio-UI scenarios target index pages instead of items (needs scenario rewrites). DOKKAI-004 ' by ' carry-over added to JA-129 trigger set. Procedure-manual F.34. | K130: 30m | L130: Native-teacher reviewer | M130: prompts/Japanese language Accuracy check.txt | O130: Not Yet Run | Q130: A73 | R130: 0%
A131: A-127 | B131: Accuracy prompt category | C131: 1 | D131: Accuracy prompt audit category A74: RATIONALE CONTENT-DISCIPLINE — copy-paste mismatch + meta-content (GOI-001..003) | E131: 1. Reference: prompts/Japanese language Accuracy check.txt A74 2. Run the category's manual sample / CI check 3. Cross-reference any JA-NN invariant noted below 4. Report findings as candidate bug rows | F131: 0 findings against current corpus snapshot OR documented false-positive class (see FP-NN catalog in same prompt). | G131: P3 | H131: Major | I131: Manual | J131: Cross-Artifact Sync 2026-05-17: per Rule 5 prompt → test-scenario sync. Source: prompts/Japanese language Accuracy check.txt A74. Hint: Added 2026-05-19 from GOI-001..003 close-out. Two rationale-content defect classes complement F.30/F.33/F.34.4. Class A (copy-paste content-mismatch, CI JA-136): no rationale_hi value (>30 chars) may be shared verbatim by 2+ questions within the same paper. Catches the GOI-001 hard learner-facing breakage where goi-6.11 rationale_hi was a byte-identical copy of goi-6.12 (about a different topic). Rejected stricter token-overlap proposal (~100 false positives from dictionary-form ↔ polite-form variation). Class B (meta-content in learner-facing rationale, CI JA-121 extended): no commit-trail / meta-doc-pointer phrases — extends JA-121 trigger set with 'Hence the rewording', 'rewording from a prior', 'from a prior version', 'documented at vocabulary_n5.md', 'documented at', 'does not bear on', 'test point this question'. Combined with existing JA-121/122/129/130, 5-invariant family on paper rationale fields. Procedure-manual F.35. | K131: 30m | L131: Native-teacher reviewer | M131: prompts/Japanese language Accuracy check.txt | O131: Not Yet Run | Q131: A74 | R131: 0%
A132: A-128 | B132: Accuracy prompt category | C132: 1 | D132: Accuracy prompt audit category A75: MIXED-SCRIPT MOJIBAKE + OFF-BY-ONE rationale_hi SHIFT + EXTENDED FIX-HISTORY (GOI-004..006) | E132: 1. Reference: prompts/Japanese language Accuracy check.txt A75 2. Run the category's manual sample / CI check 3. Cross-reference any JA-NN invariant noted below 4. Report findings as candidate bug rows | F132: 0 findings against current corpus snapshot OR documented false-positive class (see FP-NN catalog in same prompt). | G132: P3 | H132: Major | I132: Manual | J132: Cross-Artifact Sync 2026-05-17: per Rule 5 prompt → test-scenario sync. Source: prompts/Japanese language Accuracy check.txt A75. Hint: Added 2026-05-21 from GOI-004..006 close-out + horizontal mojibake sweep. Three durable rationale-content defect classes from the second goi sweep iteration. Class A (mixed-script Devanagari-inside-kana mojibake, CI JA-139): regex `[ぁ-ゖァ-ヺ一-鿿][ऀ-ॣ०-ॿ]` excluding danda U+0964/U+0965 and hyphen-separated cross-script terms. GOI-006 sample (goi-7.4 'あमारी ありません' → 'あまく ありません'); horizontal-deployment finding surfaced 2 more in dokkai-2.11 (ぐらि → ぐらい) + dokkai-3.4 (あमारी → あまり). Operational rule: corpus-wide CI pass runs BEFORE declaring class closed. Class B (narrow off-by-one rationale_hi shift, CI JA-137): 0 own-stem token overlap AND ≥2 next-Q token overlap. False-positive rate <1% vs ~21% for broad detector. GOI-004 sample (goi-7.6+goi-7.7 carried next-Q's Hindi). Class C (extended fix-history phrases, CI JA-121 trigger set extension): 11 new phrases. GOI-005 stripped 7 fields across 5 paper files. No new JA-NN for Class C (existing JA-121 intent unchanged). 7-invariant family on paper rationale fields when combined with A74. Procedure-manual F.37. | K132: 30m | L132: Native-teacher reviewer | M132: prompts/Japanese language Accuracy check.txt | O132: Not Yet Run | Q132: A75 | R132: 0%
A133: A-133 | B133: Moji content discipline | C133: A76 | D133: Moji-paper content discipline regression — per-mondai stem-emphasis convention, auto_inferred grammarPatternId on orthography, word-by-word HI rendering of EN verb constructions, EN/HI rationale character-count parity | E133: 1. Run `python tools/check_content_integrity.py` and grep for JA-140 | JA-141 | JA-142 | JA-143 PASS. 2. Optionally run tools/fix_moji_bugs_2026_05_21.py in dry-run to verify the fix scripts converge on a clean state. | F133: JA-140 + JA-141 + JA-142 + JA-143 all green. No moji stem uses markdown __X__; no moji question has grammarPatternId non-null + auto_inferred provenance; no rationale_hi contains 'के पास है पढ़ते हुए'; all EN/HI rationale pairs are within 0.6×-2.0× ratio for the entries in scope. | G133: P2 | H133: Major | I133: Automated (CI) | J133: Cross-ref: accuracy prompt §A76 + procedure-manual §F.38 + AUDIT-COVERAGE Part 34. MOJI-001..007 close-out 2026-05-21. | K133: 5 min | L133: Content auditor / QA | M133: tools/check_content_integrity.py + tools/fix_moji_bugs_2026_05_21.py | N133: 2026-05-21 | O133: PASS | P133: BUG-139..145 | Q133: — | R133: 100%
A134: A-134 | B134: Governance-doc + CI hardening | C134: A77 | D134: Governance-doc stale-content + orphaned-CI class regression — 8 durable classes (governance-doc stale state, broken cross-file ref, false-authority citation, underspecified format, indefinite bootstrapping, orphaned CI, CI-metadata ephemeral fields, cross-platform line endings) | E134: 1. python tools/check_content_integrity.py and grep JA-144 PASS. 2. gh workflow list — verify 5 workflows registered (browserstack/content-integrity/lighthouse/playwright/regen-llm-surfaces). | F134: JA-144 PASS; all 5 workflows registered; no governance-doc lacks the Document status header; no path-shaped string in any governance doc fails filesystem-resolve. | G134: P2 | H134: Major | I134: Automated (CI) | J134: Cross-ref: accuracy prompt §A77 + procedure-manual §F.39 + AUDIT-COVERAGE Part 35. DOCS-KANJI-001..004 + DOCS-VOCAB-001..004 + orphaned-workflow close-out 2026-05-21. | K134: 5 min | L134: Content auditor / DevOps | M134: tools/check_content_integrity.py + gh CLI | N134: 2026-05-21 | O134: PASS | P134: BUG-144..151 + orphaned-CI batch | Q134: — | R134: 100%
A135: A-135 | B135: Accuracy prompt category | C135: 1 | D135: Accuracy prompt audit category A78: CI-RECOVERY TRIAGE — test-side and product-side discoveries when Playwright suite first ran green (2026-05-21) | E135: 1. Reference: prompts/Japanese language Accuracy check.txt A78 2. Run the category's manual sample / CI check 3. Cross-reference any JA-NN invariant noted below 4. Report findings as candidate bug rows | F135: 0 findings against current corpus snapshot OR documented false-positive class (see FP-NN catalog in same prompt). | G135: P3 | H135: Major | I135: Manual | J135: Cross-Artifact Sync 2026-05-17: per Rule 5 prompt → test-scenario sync. Source: prompts/Japanese language Accuracy check.txt A78. Hint: Added 2026-05-21 from CI-recovery triage batch. Six durable classes from triaging 65 pre-existing failures masked by Playwright timeouts. When the suite first ran green (after parallelisation + video-off + 15-min timeout), cancellations had been hiding failures across 6 distinct classes: visual-regression OS-baseline mismatch (-win32.png vs -linux.png on CI), stale Playwright assertions against removed/restructured UI surfaces, color-contrast WCAG AA violations, recommender priority drift, etc. Generalises the discoveries so patterns are detectable by future audits. Source: AUDIT-COVERAGE Part 36. | K135: 30m | L135: Native-teacher reviewer | M135: prompts/Japanese language Accuracy check.txt | O135: Not Yet Run | Q135: A78 | R135: 0%
A136: A-136 | B136: Accuracy prompt category | C136: 1 | D136: Accuracy prompt audit category A79: PAPER-FILE source_file CANONICAL SENTINEL (DOCS-VOCAB-005) | E136: 1. Reference: prompts/Japanese language Accuracy check.txt A79 2. Run the category's manual sample / CI check 3. Cross-reference any JA-NN invariant noted below 4. Report findings as candidate bug rows | F136: 0 findings against current corpus snapshot OR documented false-positive class (see FP-NN catalog in same prompt). | G136: P3 | H136: Major | I136: Manual | J136: Cross-Artifact Sync 2026-05-17: per Rule 5 prompt → test-scenario sync. Source: prompts/Japanese language Accuracy check.txt A79. Hint: Added 2026-05-22 from DOCS-VOCAB-005 close-out. One durable defect class: a JSON metadata field that once held a real path keeps its historical breadcrumb prose long after the upstream file is deleted, embedding 'KnowledgeBank/<x>_questions_n5.md before merge on YYYY-MM-DD' style strings in 28 paper files. Canonical sentinel pattern (CI JA-145): source_file must be either (a) a path that resolves to an existing repo file, OR (b) the literal sentinel '(authored in-place)'. Other values fail. Historical breadcrumbs belong in CHANGELOG + README + git history, not in 28-files of data metadata. Closes the unaddressed-half of DOCS-VOCAB-003 (which closed prematurely as a README-only fix without touching the 28 paper files). Procedure-manual F.38. Source: AUDIT-COVERAGE Part 37. | K136: 30m | L136: Native-teacher reviewer | M136: prompts/Japanese language Accuracy check.txt | O136: Not Yet Run | Q136: A79 | R136: 0%
A137: A-137 | B137: Accuracy prompt category | C137: 1 | D137: Accuracy prompt audit category A80: COVERAGE-GAP CLOSURE — type-confusion in string fields + doc-state-vs-code-state drift (meta-audit batch) | E137: 1. Reference: prompts/Japanese language Accuracy check.txt A80 2. Run the category's manual sample / CI check 3. Cross-reference any JA-NN invariant noted below 4. Report findings as candidate bug rows | F137: 0 findings against current corpus snapshot OR documented false-positive class (see FP-NN catalog in same prompt). | G137: P3 | H137: Major | I137: Manual | J137: Cross-Artifact Sync 2026-05-17: per Rule 5 prompt → test-scenario sync. Source: prompts/Japanese language Accuracy check.txt A80. Hint: Added 2026-05-22 from meta-audit gap-closure batch. Two coverage classes the existing 147 invariants weren't designed to catch: GAP-A type-confusion in string fields (column typed as string but meant to hold specific shape like commit hash; schema accepts any string so type-checkers don't fire) and GAP-B doc-state vs code-state drift (TASKS.md [ ] items for features already shipped). N5 proof: 150/155 Fixed rows had dates in Fix Commit column instead of hashes; SVA-1.1 + SVA-1.4 were [ ] despite being shipped weeks earlier. Closed via JA-146 (strict) + tools/audit_tasks_md_against_codebase_2026_05_22.py (advisory). Reactive→proactive lesson: every JA-NN has been added AFTER a bug surfaced the pattern; no invariant authored proactively. Procedure-manual F.42. Source: AUDIT-COVERAGE Part 38. | K137: 30m | L137: Native-teacher reviewer | M137: prompts/Japanese language Accuracy check.txt | O137: Not Yet Run | Q137: A80 | R137: 0%
A138: A-138 | B138: Accuracy prompt category | C138: 1 | D138: Accuracy prompt audit category A81: GOVERNANCE-DOC CONSISTENCY DEFECTS — 5 durable classes from review-packet meta-audit (DOCS-VOCAB-006 + DOCS-CORE-001 + DOCS-BRAND-001 + DOCS-Q-001 + DOCS-DKE-001) | E138: 1. Reference: prompts/Japanese language Accuracy check.txt A81 2. Run the category's manual sample / CI check 3. Cross-reference any JA-NN invariant noted below 4. Report findings as candidate bug rows | F138: 0 findings against current corpus snapshot OR documented false-positive class (see FP-NN catalog in same prompt). | G138: P3 | H138: Major | I138: Manual | J138: Cross-Artifact Sync 2026-05-17: per Rule 5 prompt → test-scenario sync. Source: prompts/Japanese language Accuracy check.txt A81. Hint: Added 2026-05-22 from 5-bug DOCS-* close-out. Five durable defect classes generalized from the BUG-156..160 batch surfaced by review-packet meta-audit pipeline. Class A (README-vs-computed mismatch drift, CI JA-147): README documents 'Known mismatches (N)' between two data files; one side updated without the other; documented count and bulleted token set diverge from actual computed set. Class B (multi-source classification one source updated, CI JA-148): taxonomy lives in authoritative file (n5_core_pattern_ids.json) but consumers read per-entry catalog (grammar.json); reclassification not mirrored into per-entry catalog. Class C (review-packet strip undocumented in packet README): build script strips fields for privacy/anonymity; packet's own README doesn't enumerate all strip categories; reviewers misread blanked fields as bugs. Class D ('bank source' terminology overclaim): README implies source-derived relationship between corpora; actual ID overlap = 0; corpora are independent. Class E (placeholder boilerplate at-rest, CI JA-149): pre-formalization authoring leaves 'Pre-formalization (rationale not individually recorded)' placeholders that never get backfilled; placeholder ratio drifts to 28% over time. 3 of 5 classes shipped a CI invariant; 2 remain conventions documented in procedure-manual F.43. Plus the bug-spec-vs-reality verification reinforcement that rejected DOCS-VOCAB-005 as stale-snapshot artifact (audit ran on packet pre-dating b7f5787 fix). Procedure-manual F.43. Source: AUDIT-COVERAGE Part 39. | K138: 30m | L138: Native-teacher reviewer | M138: prompts/Japanese language Accuracy check.txt | O138: Not Yet Run | Q138: A81 | R138: 0%
